<?xml version="1.0" encoding="utf-8"?>
<!-- This Xacro URDF was automatically created by SolidWorks to URDF Exporter! 
     Originally created by Stephen Brawner (brawner@gmail.com) 
     Commit Version: 1.6.0-4-g7f85cfe  Build Version: 1.6.7995.38578 
     Converted to Xacro by request -->

<robot xmlns:xacro="http://wiki.ros.org/xacro"
      name="parol6">

  <link name="base_link">
      <inertial>
<origin xyz="-0.041184305190385045 -0.00205898100893484 0.046856881473507" rpy="0 0 0" />
        <mass value="1.0"/>
        <inertia ixx="0.01" ixy="0.0" ixz="0.0"
                 iyy="0.01" iyz="0.0" izz="0.01"/>
      </inertial>
      <visual>
        <origin xyz="0.0 0.0 0.0" rpy="0 0 0" />
        <geometry>
          <mesh filename="package://parol6_description/meshes/base_link.STL" scale="1.5 1.5 1.5"/>

        </geometry>
      </visual>
      <collision>
        <origin xyz="0.0 0.0 0.0" rpy="0 0 0" />
        <geometry>
          <mesh filename="package://parol6_description/meshes/base_link.STL" scale="1.5 1.5 1.5"/>
        </geometry>
      </collision>
  </link>
  <!-- <gazebo reference="base_link>
      <material>Gazebo/Orange</material>
      <turnGravityOff>false</turnGravityOff>
  </gazebo> -->

  <gazebo reference="base_link">
      <material>Gazebo/Grey</material>
  </gazebo>

  <link name="L1">
      <inertial>
        <origin xyz="0.007867948371094665 0.043458423117730655 0.14891871441793755" rpy="0 0 0" />
        <mass value="1.0"/>
        <inertia ixx="0.01" ixy="0.0" ixz="0.0"
                 iyy="0.01" iyz="0.0" izz="0.01"/>
      </inertial>
      <visual>
        <origin xyz="0.0 0.0 0.0" rpy="0 0 0" />
        <geometry>
          <mesh filename="package://parol6_description/meshes/L1.STL" scale="1.5 1.5 1.5"/>
        </geometry>
      </visual>
      <collision>
        <origin xyz="0.0 0.0 0.0" rpy="0 0 0" />
        <geometry>
          <mesh filename="package://parol6_description/meshes/L1.STL" scale="1.5 1.5 1.5"/>
        </geometry>
      </collision>
  </link>

  <gazebo reference="L1">
      <material>Gazebo/Grey</material>
  </gazebo>

  <joint name="J1" type="revolute">
      <origin xyz="0.0 0.0 0.0" rpy="0 0 0" />
      <parent link="base_link" />
      <child link="L1" />
      <axis xyz="0 0 1" />
      <limit lower="-3.14" upper="3.14" effort="10" velocity="1.0" />
  </joint>

  <link name="L2">
      <inertial>
        <origin xyz="-0.014127242579054249 -0.11758194054204076 0.055414461212659645" rpy="0 0 0" />
        <mass value="1.0"/>
        <inertia ixx="0.01" ixy="0.0" ixz="0.0"
                 iyy="0.01" iyz="0.0" izz="0.01"/>
      </inertial>
      <visual>
        <origin xyz="0.0 0.0 0.0" rpy="0 0 0" />
        <geometry>
          <mesh filename="package://parol6_description/meshes/L2.STL" scale="1.5 1.5 1.5"/>
        </geometry>
      </visual>
      <collision>
        <origin xyz="0.0 0.0 0.0" rpy="0 0 0" />
        <geometry>
          <mesh filename="package://parol6_description/meshes/L2.STL" scale="1.5 1.5 1.5"/>
        </geometry>
      </collision>
  </link>

  <gazebo reference="L2">
      <material>Gazebo/Grey</material>
  </gazebo>

  <joint name="J2" type="revolute">
      <origin xyz="0.03513108159155625 0.0 0.16575" rpy="-1.5707963267949 0 0" />
      <parent link="L1" />
      <child link="L2" />
      <axis xyz="0 0 1" />
      <limit lower="-1.57" upper="1.57" effort="10" velocity="1.0" />
  </joint>

  <link name="L3">
      <inertial>
        <origin xyz="0.02332648278593895 -0.028669152963991952 -0.00229983866875854" rpy="0 0 0" />
        <mass value="1.0"/>
        <inertia ixx="0.01" ixy="0.0" ixz="0.0"
                 iyy="0.01" iyz="0.0" izz="0.01"/>
      </inertial>
      <visual>
        <origin xyz="0.0 0.0 0.0" rpy="0 0 0" />
        <geometry>
          <mesh filename="package://parol6_description/meshes/L3.STL" scale="1.5 1.5 1.5"/>
        </geometry>
      </visual>
      <collision>
        <origin xyz="0.0 0.0 0.0" rpy="0 0 0" />
        <geometry>
          <mesh filename="package://parol6_description/meshes/L3.STL" scale="1.5 1.5 1.5"/>
        </geometry>
      </collision>
  </link>

  <gazebo reference="L3">
      <material>Gazebo/Grey</material>
  </gazebo>

  <joint name="J3" type="revolute">
      <origin xyz="0.0 -0.27 0.0" rpy="3.1416 0 -1.5708" />
      <parent link="L2" />
      <child link="L3" />
      <axis xyz="0 0 -1" />
      <limit lower="-1.57" upper="1.57" effort="10" velocity="1.0" />
  </joint>

  <link name="L4">
      <inertial>
<origin xyz="0.0014205426459516495 -0.013468420668693002 -0.13871979897405884" rpy="0 0 0" />
        <mass value="1.0"/>
        <inertia ixx="0.01" ixy="0.0" ixz="0.0"
                 iyy="0.01" iyz="0.0" izz="0.01"/>
      </inertial>
      <visual>
        <origin xyz="0.0 0.0 0.0" rpy="0 0 0" />
        <geometry>
          <mesh filename="package://parol6_description/meshes/L4.STL" scale="1.5 1.5 1.5"/>
        </geometry>
      </visual>
      <collision>
        <geometry>
           <mesh filename="package://parol6_description/meshes/L4.STL" scale="1.5 1.5 1.5"/>
        </geometry>
      </collision>
  </link>

  <gazebo reference="L4">
      <material>Gazebo/Grey</material>
  </gazebo>

  <joint name="J4" type="revolute">
      <origin xyz="0.06525 0.0 0.0" rpy="1.5708 0 3.1415" />
      <parent link="L3" />
      <child link="L4" />
      <axis xyz="0 0 1" />
      <limit lower="-1.57" upper="1.57" effort="10" velocity="1.0" />
  </joint>

  <link name="L5">
      <inertial>
        <origin xyz="1.00743257527014e-05 -0.009321314712378315 -0.001441306538874219" rpy="0 0 0" />
        <mass value="0.6249547473807983" />
        <inertia ixx="0.01" ixy="0.0" ixz="0.0"
                 iyy="0.01" iyz="0.0" izz="0.01"/>
      </inertial>

      <visual>
        <origin xyz="0.0 0.0 0.0" rpy="0 0 0" />
        <geometry>
          <mesh filename="package://parol6_description/meshes/L5.STL" scale="1.5 1.5 1.5"/>
        </geometry>
      </visual>
      <collision>
        <origin xyz="0.0 0.0 0.0" rpy="0 0 0" />
        <geometry>
          <mesh filename="package://parol6_description/meshes/L5.STL" scale="1.5 1.5 1.5"/>
        </geometry>
      </collision>
  </link>

  <gazebo reference="L5">
      <material>Gazebo/Grey</material>
  </gazebo>

  <joint name="J5" type="revolute">
      <origin xyz="0.0 0.0 -0.264525" rpy="-1.5708 0 0" />
      <parent link="L4" />
      <child link="L5" />
      <axis xyz="0 0 -1" />
        <limit lower="-1.57" upper="1.57" effort="10" velocity="1.0" />
  </joint>

  <link name="L6">
      
      <inertial>
        <origin xyz="0.009494326308420224 -0.000680784528142533 -0.0831662351079891" rpy="0 0 0" />
        <mass value="0.23735072609947158" />
        <inertia ixx="0.01" ixy="0.0" ixz="0.0"
                 iyy="0.01" iyz="0.0" izz="0.01"/>
      </inertial>
      <visual>
        <origin xyz="0.0 0.0 0.0" rpy="0 0 0" />
        <geometry>
          <mesh filename="package://parol6_description/meshes/vaccum_gripper_holder.stl" scale="1.5 1.5 1.5"/>
        </geometry>
      </visual>
      <collision>
        <origin xyz="0.0 0.0 0.0" rpy="0 0 0" />
        <geometry>
          <mesh filename="package://parol6_description/meshes/vaccum_gripper_holder.stl" scale="1.5 1.5 1.5"/>
        </geometry>
      </collision>
  </link>

  <gazebo reference="L6">
      <material>Gazebo/Orange</material>
  </gazebo>

  <joint name="J6" type="continuous">
      <origin xyz="0.0 0.0 0.0" rpy="1.5708 0 0" />
      <parent link="L5" />
      <child link="L6" />
      <axis xyz="0 0 -1" />
      <limit lower="-1.57" upper="1.57" effort="10" velocity="1.0" />
  </joint>


  <link name="suction_gripper">
      <visual>
        <origin xyz="0.0 0.0 0.0" rpy="0 0 0"/>
        <geometry>
          <mesh filename="package://parol6_description/meshes/vaccum_gripper.stl" scale="1.5 1.5 1.5"/>
        </geometry>
      </visual>
      <collision>
        <origin xyz="0.0 0.0 0.0" rpy="0 0 0"/>
        <geometry>
          <mesh filename="package://parol6_description/meshes/vaccum_gripper.stl" scale="1.5 1.5 1.5"/>
        </geometry>
      </collision>
      
      <inertial>
        <origin xyz="0 0 0" rpy="0 0 0"/>
        <mass value="1.0"/>
        <inertia ixx="0.01" ixy="0.0" ixz="0.0"
                 iyy="0.01" iyz="0.0" izz="0.01"/>
      </inertial>

  </link>

  <gazebo reference="suction_gripper">
      <material>Gazebo/Orange</material>
  </gazebo>


  <joint name="J7" type="fixed">
      <parent link="L6"/>
      <child link="suction_gripper"/>
      <origin xyz="0.0 0.0 0.0" rpy="0 0 0"/>
  </joint>


  <link name="tool0"/>
  <gazebo reference="tool0">
      <material>Gazebo/Yellow</material>
  </gazebo>


  <joint name="tool0_fixed" type="fixed">
      <parent link="suction_gripper"/>
      <child link="tool0"/>
      <origin xyz="0.1255425 -0.0011684999999999998 -0.0904575" rpy="0 0 0"/>
  </joint>


</robot>
