<?xml version="1.0" encoding="utf-8"?>
<!-- This Xacro URDF was automatically created by SolidWorks to URDF Exporter! 
     Originally created by Stephen Brawner (brawner@gmail.com) 
     Commit Version: 1.6.0-4-g7f85cfe  Build Version: 1.6.7995.38578 
     Converted to Xacro by request -->

<robot xmlns:xacro="http://wiki.ros.org/xacro"
      name="parol6">

  <link name="base_link">
      <inertial>
        <origin xyz="-0.041184305190385045 -0.00205898100893484 0.046856881473507" rpy="0 0 0" />
        <mass value="2.742731859859236" />
        <inertia ixx="0.008409339977597758" ixy="0.00035498008104013193" ixz="6.43854268273456e-05"
                iyy="0.00106582362830227" iyz="-2.6194130573118E-06" izz="0.00147883396699374" />
      </inertial>
      <visual>
        <origin xyz="0.0 0.0 0.0" rpy="0 0 0" />
        <geometry>
          <mesh filename="file:///home/azif/projetcs/parol6/parol6_description/meshes/base_link.STL" scale="1.5 1.5 1.5"/>

        </geometry>
      </visual>
      <collision>
        <origin xyz="0.0 0.0 0.0" rpy="0 0 0" />
        <geometry>
          <mesh filename="file:///home/azif/projetcs/parol6/parol6_description/meshes/base_link.STL" scale="1.5 1.5 1.5"/>
        </geometry>
      </collision>
  </link>
  <!-- <gazebo reference="base_link>
      <material>Gazebo/Orange</material>
      <turnGravityOff>false</turnGravityOff>
  </gazebo> -->

  <gazebo reference="base_link">
      <material>Gazebo/Grey</material>
  </gazebo>

  <link name="L1">
      <inertial>
        <origin xyz="0.007867948371094665 0.043458423117730655 0.14891871441793755" rpy="0 0 0" />
        <mass value="2.176202803039536" />
        <inertia ixx="0.00830979574815275" ixy="-0.0004762472512681331" ixz="-0.00043319827397273435"
                iyy="0.00056996197700816" iyz="-0.000121686402940313" izz="0.00129487722474286" />
      </inertial>
      <visual>
        <origin xyz="0.0 0.0 0.0" rpy="0 0 0" />
        <geometry>
          <mesh filename="file:///home/azif/projetcs/parol6/parol6_description/meshes/L1.STL" scale="1.5 1.5 1.5"/>
        </geometry>
      </visual>
      <collision>
        <origin xyz="0.0 0.0 0.0" rpy="0 0 0" />
        <geometry>
          <mesh filename="file:///home/azif/projetcs/parol6/parol6_description/meshes/L1.STL" scale="1.5 1.5 1.5"/>
        </geometry>
      </collision>
  </link>

  <gazebo reference="L1">
      <material>Gazebo/Grey</material>
  </gazebo>

  <joint name="J1" type="revolute">
      <origin xyz="0.0 0.0 0.0" rpy="0 0 0" />
      <parent link="base_link" />
      <child link="L1" />
      <axis xyz="0 0 1" />
      <limit lower="-3.14" upper="3.14" effort="0" velocity="0" />
  </joint>

  <link name="L2">
      <inertial>
        <origin xyz="-0.014127242579054249 -0.11758194054204076 0.055414461212659645" rpy="0 0 0" />
        <mass value="1.7291298804742845" />
        <inertia ixx="0.009367458838496387" ixy="2.7583251830485166e-05" ixz="-2.5122749243172585e-06"
                iyy="0.000205462733796053" iyz="4.86441772103282E-07" izz="0.00132225033266162" />
      </inertial>
      <visual>
        <origin xyz="0.0 0.0 0.0" rpy="0 0 0" />
        <geometry>
          <mesh filename="file:///home/azif/projetcs/parol6/parol6_description/meshes/L2.STL" scale="1.5 1.5 1.5"/>
        </geometry>
      </visual>
      <collision>
        <origin xyz="0.0 0.0 0.0" rpy="0 0 0" />
        <geometry>
          <mesh filename="file:///home/azif/projetcs/parol6/parol6_description/meshes/L2.STL" scale="1.5 1.5 1.5"/>
        </geometry>
      </collision>
  </link>

  <gazebo reference="L2">
      <material>Gazebo/Grey</material>
  </gazebo>

  <joint name="J2" type="revolute">
      <origin xyz="0.03513108159155625 0.0 0.16575" rpy="-1.5707963267949 0 0" />
      <parent link="L1" />
      <child link="L2" />
      <axis xyz="0 0 1" />
      <limit lower="-1.57" upper="1.57" effort="0" velocity="0" />
  </joint>

  <link name="L3">
      <inertial>
        <origin xyz="0.02332648278593895 -0.028669152963991952 -0.00229983866875854" rpy="0 0 0" />
        <mass value="1.8595271175953985" />
        <inertia ixx="0.004391281345342044" ixy="0.0008847116079475719" ixz="-9.109105081666456e-05"
                iyy="0.000567011676944701" iyz="1.55814255036021E-05" izz="0.000815862001506843" />
      </inertial>
      <visual>
        <origin xyz="0.0 0.0 0.0" rpy="0 0 0" />
        <geometry>
          <mesh filename="file:///home/azif/projetcs/parol6/parol6_description/meshes/L3.STL" scale="1.5 1.5 1.5"/>
        </geometry>
      </visual>
      <collision>
        <origin xyz="0.0 0.0 0.0" rpy="0 0 0" />
        <geometry>
          <mesh filename="file:///home/azif/projetcs/parol6/parol6_description/meshes/L3.STL" scale="1.5 1.5 1.5"/>
        </geometry>
      </collision>
  </link>

  <gazebo reference="L3">
      <material>Gazebo/Grey</material>
  </gazebo>

  <joint name="J3" type="revolute">
      <origin xyz="0.0 -0.27 0.0" rpy="3.1416 0 -1.5708" />
      <parent link="L2" />
      <child link="L3" />
      <axis xyz="0 0 -1" />
      <limit lower="-1.57" upper="1.57" effort="0" velocity="0" />
  </joint>

  <link name="L4">
      <inertial>
        <origin xyz="0.0014205426459516495 -0.013468420668693002 -0.13871979897405884" rpy="0 0 0" />
        <mass value="1.3279397388946312" />
        <inertia ixx="0.0028223881746794453" ixy="-8.015962550603914e-05" ixz="-1.191455163645413e-06"
                iyy="0.000332364226344361" iyz="-6.10397110934672E-05" izz="0.000250606789571909" />
      </inertial>
      <visual>
        <origin xyz="0.0 0.0 0.0" rpy="0 0 0" />
        <geometry>
          <mesh filename="file:///home/azif/projetcs/parol6/parol6_description/meshes/L4.STL" scale="1.5 1.5 1.5"/>
        </geometry>
      </visual>
      <collision>
        <geometry>
           <mesh filename="file:///home/azif/projetcs/parol6/parol6_description/meshes/L4.STL" scale="1.5 1.5 1.5"/>
        </geometry>
      </collision>
  </link>

  <gazebo reference="L4">
      <material>Gazebo/Grey</material>
  </gazebo>

  <joint name="J4" type="revolute">
      <origin xyz="0.06525 0.0 0.0" rpy="1.5708 0 3.1415" />
      <parent link="L3" />
      <child link="L4" />
      <axis xyz="0 0 1" />
      <limit lower="-1.57" upper="1.57" effort="0" velocity="0" />
  </joint>

  <link name="L5">
      <inertial>
        <origin xyz="1.00743257527014e-05 -0.009321314712378315 -0.001441306538874219" rpy="0 0 0" />
        <mass value="0.6249547473807983" />
        <inertia
          ixx="0.000109176748460021"
          ixy="-1.27195013439061E-07"
          ixz="8.4436049148633E-08"
          iyy="8.41307588934268E-05"
          iyz="-4.41596193640049E-07"
          izz="0.000110629136236229" />
      </inertial>
      <visual>
        <origin xyz="0.0 0.0 0.0" rpy="0 0 0" />
        <geometry>
          <mesh filename="file:///home/azif/projetcs/parol6/parol6_description/meshes/L5.STL" scale="1.5 1.5 1.5"/>
        </geometry>
      </visual>
      <collision>
        <origin xyz="0.0 0.0 0.0" rpy="0 0 0" />
        <geometry>
          <mesh filename="file:///home/azif/projetcs/parol6/parol6_description/meshes/L5.STL" scale="1.5 1.5 1.5"/>
        </geometry>
      </collision>
  </link>

  <gazebo reference="L5">
      <material>Gazebo/Grey</material>
  </gazebo>

  <joint name="J5" type="revolute">
      <origin xyz="0.0 0.0 -0.264525" rpy="-1.5708 0 0" />
      <parent link="L4" />
      <child link="L5" />
      <axis xyz="0 0 -1" />
        <limit lower="-1.57" upper="1.57" effort="0" velocity="0" />
  </joint>

  <link name="L6">
      <inertial>
        <origin xyz="0.009494326308420224 -0.000680784528142533 -0.0831662351079891" rpy="0 0 0" />
        <mass value="0.23735072609947158" />
        <inertia
          ixx="1.40276237518287E-05"
          ixy="3.15503246005279E-07"
          ixz="-9.28469598788221E-07"
          iyy="1.81406721166117E-05"
          iyz="-9.43630009030796E-07"
          izz="2.34608103291027E-05" />
      </inertial>
      <visual>
        <origin xyz="0.0 0.0 0.0" rpy="0 0 0" />
        <geometry>
          <mesh filename="file:///home/azif/projetcs/parol6/parol6_description/meshes/vaccum_gripper_holder.stl" scale="1.5 1.5 1.5"/>
        </geometry>
      </visual>
      <collision>
        <origin xyz="0.0 0.0 0.0" rpy="0 0 0" />
        <geometry>
          <mesh filename="file:///home/azif/projetcs/parol6/parol6_description/meshes/vaccum_gripper_holder.stl" scale="1.5 1.5 1.5"/>
        </geometry>
      </collision>
  </link>

  <gazebo reference="L6">
      <material>Gazebo/Orange</material>
  </gazebo>

  <joint name="J6" type="continuous">
      <origin xyz="0.0 0.0 0.0" rpy="1.5708 0 0" />
      <parent link="L5" />
      <child link="L6" />
      <axis xyz="0 0 -1" />
      <limit lower="0" upper="0" effort="0" velocity="0" />
  </joint>


  <link name="suction_gripper">
      <visual>
        <origin xyz="0.0 0.0 0.0" rpy="0 0 0"/>
        <geometry>
          <mesh filename="file:///home/azif/projetcs/parol6/parol6_description/meshes/vaccum_gripper.stl" scale="1.5 1.5 1.5"/>
        </geometry>
      </visual>
      <collision>
        <origin xyz="0.0 0.0 0.0" rpy="0 0 0"/>
        <geometry>
          <mesh filename="file:///home/azif/projetcs/parol6/parol6_description/meshes/vaccum_gripper.stl" scale="1.5 1.5 1.5"/>
        </geometry>
      </collision>
      <inertial>
        <origin xyz="0.0 0.0 0.0" rpy="0 0 0"/>
        <mass value="0.03375"/>
        <inertia
          ixx="1e-6" ixy="0" ixz="0"
          iyy="1e-6" iyz="0"
          izz="1e-6"/>
      </inertial>
  </link>

  <gazebo reference="suction_gripper">
      <material>Gazebo/Orange</material>
  </gazebo>


  <joint name="J7" type="fixed">
      <parent link="L6"/>
      <child link="suction_gripper"/>
      <origin xyz="0.0 0.0 0.0" rpy="0 0 0"/>
  </joint>


  <link name="tool0"/>
  <gazebo reference="tool0">
      <material>Gazebo/Yellow</material>
  </gazebo>


  <joint name="tool0_fixed" type="fixed">
      <parent link="suction_gripper"/>
      <child link="tool0"/>
      <origin xyz="0.1255425 -0.0011684999999999998 -0.0904575" rpy="0 0 0"/>
  </joint>


</robot>
